[Thu Apr 13 20:41:35.033363 2017] [:error] [pid 30754:tid 140484445353728] [client 14.140.161.92:64662] mod_wsgi (pid=30754): Target WSGI script '/var/www/api/wsgi/flask.wsgi' cannot be loaded as Python module.
[Thu Apr 13 20:41:35.033458 2017] [:error] [pid 30754:tid 140484445353728] [client 14.140.161.92:64662] mod_wsgi (pid=30754): Exception occurred processing WSGI script '/var/www/api/wsgi/flask.wsgi'.
[Thu Apr 13 20:41:35.033492 2017] [:error] [pid 30754:tid 140484445353728] [client 14.140.161.92:64662] Traceback (most recent call last):
[Thu Apr 13 20:41:35.033524 2017] [:error] [pid 30754:tid 140484445353728] [client 14.140.161.92:64662]   File "/var/www/api/wsgi/flask.wsgi", line 7, in <module>
[Thu Apr 13 20:41:35.033615 2017] [:error] [pid 30754:tid 140484445353728] [client 14.140.161.92:64662]     from app import app as application
[Thu Apr 13 20:41:35.033633 2017] [:error] [pid 30754:tid 140484445353728] [client 14.140.161.92:64662]   File "/var/www/api/app.py", line 1, in <module>
[Thu Apr 13 20:41:35.033694 2017] [:error] [pid 30754:tid 140484445353728] [client 14.140.161.92:64662]     from flask import Flask
[Thu Apr 13 20:41:35.033709 2017] [:error] [pid 30754:tid 140484445353728] [client 14.140.161.92:64662]   File "/usr/local/lib/python2.7/dist-packages/flask/__init__.py", line 17, in <module>
[Thu Apr 13 20:41:35.036191 2017] [:error] [pid 30754:tid 140484445353728] [client 14.140.161.92:64662]     from werkzeug.exceptions import abort
[Thu Apr 13 20:41:35.036225 2017] [:error] [pid 30754:tid 140484445353728] [client 14.140.161.92:64662]   File "/usr/local/lib/python2.7/dist-packages/werkzeug/__init__.py", line 152, in <module>
[Thu Apr 13 20:41:35.038554 2017] [:error] [pid 30754:tid 140484445353728] [client 14.140.161.92:64662]     __import__('werkzeug.exceptions')
[Thu Apr 13 20:41:35.038586 2017] [:error] [pid 30754:tid 140484445353728] [client 14.140.161.92:64662]   File "/usr/local/lib/python2.7/dist-packages/werkzeug/exceptions.py", line 71, in <module>
[Thu Apr 13 20:41:35.046638 2017] [:error] [pid 30754:tid 140484445353728] [client 14.140.161.92:64662]     from werkzeug.wrappers import Response
[Thu Apr 13 20:41:35.046691 2017] [:error] [pid 30754:tid 140484445353728] [client 14.140.161.92:64662]   File "/usr/local/lib/python2.7/dist-packages/werkzeug/wrappers.py", line 26, in <module>
[Thu Apr 13 20:41:35.060108 2017] [:error] [pid 30754:tid 140484445353728] [client 14.140.161.92:64662]     from werkzeug.http import HTTP_STATUS_CODES, \\
[Thu Apr 13 20:41:35.060163 2017] [:error] [pid 30754:tid 140484445353728] [client 14.140.161.92:64662]   File "/usr/local/lib/python2.7/dist-packages/werkzeug/http.py", line 22, in <module>
[Thu Apr 13 20:41:35.066457 2017] [:error] [pid 30754:tid 140484445353728] [client 14.140.161.92:64662]     from email.utils import parsedate_tz
[Thu Apr 13 20:41:35.066511 2017] [:error] [pid 30754:tid 140484445353728] [client 14.140.161.92:64662]   File "/var/www/api/email/__init__.py", line 1, in <module>
[Thu Apr 13 20:41:35.066591 2017] [:error] [pid 30754:tid 140484445353728] [client 14.140.161.92:64662]     from email_v1 import *
[Thu Apr 13 20:41:35.066670 2017] [:error] [pid 30754:tid 140484445353728] [client 14.140.161.92:64662]   File "/var/www/api/email/email_v1.py", line 23
[Thu Apr 13 20:41:35.066675 2017] [:error] [pid 30754:tid 140484445353728] [client 14.140.161.92:64662]     subject = "Welcome to Roofpik "+_name"!"
[Thu Apr 13 20:41:35.066679 2017] [:error] [pid 30754:tid 140484445353728] [client 14.140.161.92:64662]                                            ^
[Thu Apr 13 20:41:35.066681 2017] [:error] [pid 30754:tid 140484445353728] [client 14.140.161.92:64662] SyntaxError: invalid syntax
[Thu Apr 13 20:42:17.542392 2017] [:error] [pid 30873:tid 140592784791296] [client 14.140.161.92:64668] mod_wsgi (pid=30873): Target WSGI script '/var/www/api/wsgi/flask.wsgi' cannot be loaded as Python module.
[Thu Apr 13 20:42:17.542455 2017] [:error] [pid 30873:tid 140592784791296] [client 14.140.161.92:64668] mod_wsgi (pid=30873): Exception occurred processing WSGI script '/var/www/api/wsgi/flask.wsgi'.
[Thu Apr 13 20:42:17.542490 2017] [:error] [pid 30873:tid 140592784791296] [client 14.140.161.92:64668] Traceback (most recent call last):
[Thu Apr 13 20:42:17.542514 2017] [:error] [pid 30873:tid 140592784791296] [client 14.140.161.92:64668]   File "/var/www/api/wsgi/flask.wsgi", line 7, in <module>
[Thu Apr 13 20:42:17.542579 2017] [:error] [pid 30873:tid 140592784791296] [client 14.140.161.92:64668]     from app import app as application
[Thu Apr 13 20:42:17.542589 2017] [:error] [pid 30873:tid 140592784791296] [client 14.140.161.92:64668]   File "/var/www/api/app.py", line 1, in <module>
[Thu Apr 13 20:42:17.542628 2017] [:error] [pid 30873:tid 140592784791296] [client 14.140.161.92:64668]     from flask import Flask
[Thu Apr 13 20:42:17.542640 2017] [:error] [pid 30873:tid 140592784791296] [client 14.140.161.92:64668]   File "/usr/local/lib/python2.7/dist-packages/flask/__init__.py", line 17, in <module>
[Thu Apr 13 20:42:17.542677 2017] [:error] [pid 30873:tid 140592784791296] [client 14.140.161.92:64668]     from werkzeug.exceptions import abort
[Thu Apr 13 20:42:17.542685 2017] [:error] [pid 30873:tid 140592784791296] [client 14.140.161.92:64668]   File "/usr/local/lib/python2.7/dist-packages/werkzeug/__init__.py", line 152, in <module>
[Thu Apr 13 20:42:17.542774 2017] [:error] [pid 30873:tid 140592784791296] [client 14.140.161.92:64668]     __import__('werkzeug.exceptions')
[Thu Apr 13 20:42:17.542786 2017] [:error] [pid 30873:tid 140592784791296] [client 14.140.161.92:64668]   File "/usr/local/lib/python2.7/dist-packages/werkzeug/exceptions.py", line 71, in <module>
[Thu Apr 13 20:42:17.542936 2017] [:error] [pid 30873:tid 140592784791296] [client 14.140.161.92:64668]     from werkzeug.wrappers import Response
[Thu Apr 13 20:42:17.542948 2017] [:error] [pid 30873:tid 140592784791296] [client 14.140.161.92:64668]   File "/usr/local/lib/python2.7/dist-packages/werkzeug/wrappers.py", line 26, in <module>
[Thu Apr 13 20:42:17.543451 2017] [:error] [pid 30873:tid 140592784791296] [client 14.140.161.92:64668]     from werkzeug.http import HTTP_STATUS_CODES, \\
[Thu Apr 13 20:42:17.543465 2017] [:error] [pid 30873:tid 140592784791296] [client 14.140.161.92:64668]   File "/usr/local/lib/python2.7/dist-packages/werkzeug/http.py", line 22, in <module>
[Thu Apr 13 20:42:17.543672 2017] [:error] [pid 30873:tid 140592784791296] [client 14.140.161.92:64668]     from email.utils import parsedate_tz
[Thu Apr 13 20:42:17.543681 2017] [:error] [pid 30873:tid 140592784791296] [client 14.140.161.92:64668]   File "/var/www/api/email/__init__.py", line 1, in <module>
[Thu Apr 13 20:42:17.543704 2017] [:error] [pid 30873:tid 140592784791296] [client 14.140.161.92:64668]     from email_v1 import *
[Thu Apr 13 20:42:17.543747 2017] [:error] [pid 30873:tid 140592784791296] [client 14.140.161.92:64668]   File "/var/www/api/email/email_v1.py", line 31
[Thu Apr 13 20:42:17.543751 2017] [:error] [pid 30873:tid 140592784791296] [client 14.140.161.92:64668]     
[Thu Apr 13 20:42:17.543754 2017] [:error] [pid 30873:tid 140592784791296] [client 14.140.161.92:64668]     ^
[Thu Apr 13 20:42:17.543756 2017] [:error] [pid 30873:tid 140592784791296] [client 14.140.161.92:64668] IndentationError: unexpected unindent
[Thu Apr 13 20:44:17.349002 2017] [:error] [pid 30984:tid 140150056625920] [client 14.140.161.92:64673] mod_wsgi (pid=30984): Target WSGI script '/var/www/api/wsgi/flask.wsgi' cannot be loaded as Python module.
[Thu Apr 13 20:44:17.349147 2017] [:error] [pid 30984:tid 140150056625920] [client 14.140.161.92:64673] mod_wsgi (pid=30984): Exception occurred processing WSGI script '/var/www/api/wsgi/flask.wsgi'.
[Thu Apr 13 20:44:17.353173 2017] [:error] [pid 30984:tid 140150056625920] [client 14.140.161.92:64673] Traceback (most recent call last):
[Thu Apr 13 20:44:17.353235 2017] [:error] [pid 30984:tid 140150056625920] [client 14.140.161.92:64673]   File "/var/www/api/wsgi/flask.wsgi", line 7, in <module>
[Thu Apr 13 20:44:17.353491 2017] [:error] [pid 30984:tid 140150056625920] [client 14.140.161.92:64673]     from app import app as application
[Thu Apr 13 20:44:17.353582 2017] [:error] [pid 30984:tid 140150056625920] [client 14.140.161.92:64673]   File "/var/www/api/app.py", line 1, in <module>
[Thu Apr 13 20:44:17.353736 2017] [:error] [pid 30984:tid 140150056625920] [client 14.140.161.92:64673]     from flask import Flask
[Thu Apr 13 20:44:17.353758 2017] [:error] [pid 30984:tid 140150056625920] [client 14.140.161.92:64673]   File "/usr/local/lib/python2.7/dist-packages/flask/__init__.py", line 17, in <module>
[Thu Apr 13 20:44:17.353838 2017] [:error] [pid 30984:tid 140150056625920] [client 14.140.161.92:64673]     from werkzeug.exceptions import abort
[Thu Apr 13 20:44:17.353856 2017] [:error] [pid 30984:tid 140150056625920] [client 14.140.161.92:64673]   File "/usr/local/lib/python2.7/dist-packages/werkzeug/__init__.py", line 152, in <module>
[Thu Apr 13 20:44:17.353969 2017] [:error] [pid 30984:tid 140150056625920] [client 14.140.161.92:64673]     __import__('werkzeug.exceptions')
[Thu Apr 13 20:44:17.353988 2017] [:error] [pid 30984:tid 140150056625920] [client 14.140.161.92:64673]   File "/usr/local/lib/python2.7/dist-packages/werkzeug/exceptions.py", line 71, in <module>
[Thu Apr 13 20:44:17.354265 2017] [:error] [pid 30984:tid 140150056625920] [client 14.140.161.92:64673]     from werkzeug.wrappers import Response
[Thu Apr 13 20:44:17.354285 2017] [:error] [pid 30984:tid 140150056625920] [client 14.140.161.92:64673]   File "/usr/local/lib/python2.7/dist-packages/werkzeug/wrappers.py", line 26, in <module>
[Thu Apr 13 20:44:17.355000 2017] [:error] [pid 30984:tid 140150056625920] [client 14.140.161.92:64673]     from werkzeug.http import HTTP_STATUS_CODES, \\
[Thu Apr 13 20:44:17.355025 2017] [:error] [pid 30984:tid 140150056625920] [client 14.140.161.92:64673]   File "/usr/local/lib/python2.7/dist-packages/werkzeug/http.py", line 22, in <module>
[Thu Apr 13 20:44:17.355323 2017] [:error] [pid 30984:tid 140150056625920] [client 14.140.161.92:64673]     from email.utils import parsedate_tz
[Thu Apr 13 20:44:17.355344 2017] [:error] [pid 30984:tid 140150056625920] [client 14.140.161.92:64673]   File "/var/www/api/email/__init__.py", line 1, in <module>
[Thu Apr 13 20:44:17.355396 2017] [:error] [pid 30984:tid 140150056625920] [client 14.140.161.92:64673]     from email_v1 import *
[Thu Apr 13 20:44:17.355475 2017] [:error] [pid 30984:tid 140150056625920] [client 14.140.161.92:64673]   File "/var/www/api/email/email_v1.py", line 29
[Thu Apr 13 20:44:17.355488 2017] [:error] [pid 30984:tid 140150056625920] [client 14.140.161.92:64673]     
[Thu Apr 13 20:44:17.355493 2017] [:error] [pid 30984:tid 140150056625920] [client 14.140.161.92:64673]     ^
[Thu Apr 13 20:44:17.355497 2017] [:error] [pid 30984:tid 140150056625920] [client 14.140.161.92:64673] IndentationError: unexpected unindent
[Thu Apr 13 20:45:36.381438 2017] [:error] [pid 31097:tid 139874904553216] [client 14.140.161.92:64678] mod_wsgi (pid=31097): Target WSGI script '/var/www/api/wsgi/flask.wsgi' cannot be loaded as Python module.
[Thu Apr 13 20:45:36.381604 2017] [:error] [pid 31097:tid 139874904553216] [client 14.140.161.92:64678] mod_wsgi (pid=31097): Exception occurred processing WSGI script '/var/www/api/wsgi/flask.wsgi'.
[Thu Apr 13 20:45:36.381932 2017] [:error] [pid 31097:tid 139874904553216] [client 14.140.161.92:64678] Traceback (most recent call last):
[Thu Apr 13 20:45:36.381969 2017] [:error] [pid 31097:tid 139874904553216] [client 14.140.161.92:64678]   File "/var/www/api/wsgi/flask.wsgi", line 7, in <module>
[Thu Apr 13 20:45:36.382170 2017] [:error] [pid 31097:tid 139874904553216] [client 14.140.161.92:64678]     from app import app as application
[Thu Apr 13 20:45:36.382188 2017] [:error] [pid 31097:tid 139874904553216] [client 14.140.161.92:64678]   File "/var/www/api/app.py", line 1, in <module>
[Thu Apr 13 20:45:36.382236 2017] [:error] [pid 31097:tid 139874904553216] [client 14.140.161.92:64678]     from flask import Flask
[Thu Apr 13 20:45:36.382246 2017] [:error] [pid 31097:tid 139874904553216] [client 14.140.161.92:64678]   File "/usr/local/lib/python2.7/dist-packages/flask/__init__.py", line 17, in <module>
[Thu Apr 13 20:45:36.382292 2017] [:error] [pid 31097:tid 139874904553216] [client 14.140.161.92:64678]     from werkzeug.exceptions import abort
[Thu Apr 13 20:45:36.382302 2017] [:error] [pid 31097:tid 139874904553216] [client 14.140.161.92:64678]   File "/usr/local/lib/python2.7/dist-packages/werkzeug/__init__.py", line 152, in <module>
[Thu Apr 13 20:45:36.382355 2017] [:error] [pid 31097:tid 139874904553216] [client 14.140.161.92:64678]     __import__('werkzeug.exceptions')
[Thu Apr 13 20:45:36.382364 2017] [:error] [pid 31097:tid 139874904553216] [client 14.140.161.92:64678]   File "/usr/local/lib/python2.7/dist-packages/werkzeug/exceptions.py", line 71, in <module>
[Thu Apr 13 20:45:36.382492 2017] [:error] [pid 31097:tid 139874904553216] [client 14.140.161.92:64678]     from werkzeug.wrappers import Response
[Thu Apr 13 20:45:36.382501 2017] [:error] [pid 31097:tid 139874904553216] [client 14.140.161.92:64678]   File "/usr/local/lib/python2.7/dist-packages/werkzeug/wrappers.py", line 26, in <module>
[Thu Apr 13 20:45:36.383056 2017] [:error] [pid 31097:tid 139874904553216] [client 14.140.161.92:64678]     from werkzeug.http import HTTP_STATUS_CODES, \\
[Thu Apr 13 20:45:36.383076 2017] [:error] [pid 31097:tid 139874904553216] [client 14.140.161.92:64678]   File "/usr/local/lib/python2.7/dist-packages/werkzeug/http.py", line 24, in <module>
[Thu Apr 13 20:45:36.383310 2017] [:error] [pid 31097:tid 139874904553216] [client 14.140.161.92:64678]     from email.Utils import parsedate_tz
[Thu Apr 13 20:45:36.383322 2017] [:error] [pid 31097:tid 139874904553216] [client 14.140.161.92:64678]   File "/var/www/api/email/__init__.py", line 1, in <module>
[Thu Apr 13 20:45:36.383349 2017] [:error] [pid 31097:tid 139874904553216] [client 14.140.161.92:64678]     from email_v1 import *
[Thu Apr 13 20:45:36.383358 2017] [:error] [pid 31097:tid 139874904553216] [client 14.140.161.92:64678]   File "/var/www/api/email/email_v1.py", line 2, in <module>
[Thu Apr 13 20:45:36.383388 2017] [:error] [pid 31097:tid 139874904553216] [client 14.140.161.92:64678]     from flask import request
[Thu Apr 13 20:45:36.383414 2017] [:error] [pid 31097:tid 139874904553216] [client 14.140.161.92:64678] ImportError: cannot import name request
[Thu Apr 13 20:47:39.838028 2017] [:error] [pid 31204:tid 140522505058048] [client 14.140.161.92:64684] mod_wsgi (pid=31204): Target WSGI script '/var/www/api/wsgi/flask.wsgi' cannot be loaded as Python module.
[Thu Apr 13 20:47:39.838085 2017] [:error] [pid 31204:tid 140522505058048] [client 14.140.161.92:64684] mod_wsgi (pid=31204): Exception occurred processing WSGI script '/var/www/api/wsgi/flask.wsgi'.
[Thu Apr 13 20:47:39.838108 2017] [:error] [pid 31204:tid 140522505058048] [client 14.140.161.92:64684] Traceback (most recent call last):
[Thu Apr 13 20:47:39.838130 2017] [:error] [pid 31204:tid 140522505058048] [client 14.140.161.92:64684]   File "/var/www/api/wsgi/flask.wsgi", line 7, in <module>
[Thu Apr 13 20:47:39.838191 2017] [:error] [pid 31204:tid 140522505058048] [client 14.140.161.92:64684]     from app import app as application
[Thu Apr 13 20:47:39.838200 2017] [:error] [pid 31204:tid 140522505058048] [client 14.140.161.92:64684]   File "/var/www/api/app.py", line 1, in <module>
[Thu Apr 13 20:47:39.838234 2017] [:error] [pid 31204:tid 140522505058048] [client 14.140.161.92:64684]     from flask import Flask
[Thu Apr 13 20:47:39.838242 2017] [:error] [pid 31204:tid 140522505058048] [client 14.140.161.92:64684]   File "/usr/local/lib/python2.7/dist-packages/flask/__init__.py", line 17, in <module>
[Thu Apr 13 20:47:39.838274 2017] [:error] [pid 31204:tid 140522505058048] [client 14.140.161.92:64684]     from werkzeug.exceptions import abort
[Thu Apr 13 20:47:39.838282 2017] [:error] [pid 31204:tid 140522505058048] [client 14.140.161.92:64684]   File "/usr/local/lib/python2.7/dist-packages/werkzeug/__init__.py", line 152, in <module>
[Thu Apr 13 20:47:39.838334 2017] [:error] [pid 31204:tid 140522505058048] [client 14.140.161.92:64684]     __import__('werkzeug.exceptions')
[Thu Apr 13 20:47:39.838353 2017] [:error] [pid 31204:tid 140522505058048] [client 14.140.161.92:64684]   File "/usr/local/lib/python2.7/dist-packages/werkzeug/exceptions.py", line 71, in <module>
[Thu Apr 13 20:47:39.838530 2017] [:error] [pid 31204:tid 140522505058048] [client 14.140.161.92:64684]     from werkzeug.wrappers import Response
[Thu Apr 13 20:47:39.838542 2017] [:error] [pid 31204:tid 140522505058048] [client 14.140.161.92:64684]   File "/usr/local/lib/python2.7/dist-packages/werkzeug/wrappers.py", line 26, in <module>
[Thu Apr 13 20:47:39.838998 2017] [:error] [pid 31204:tid 140522505058048] [client 14.140.161.92:64684]     from werkzeug.http import HTTP_STATUS_CODES, \\
[Thu Apr 13 20:47:39.839013 2017] [:error] [pid 31204:tid 140522505058048] [client 14.140.161.92:64684]   File "/usr/local/lib/python2.7/dist-packages/werkzeug/http.py", line 24, in <module>
[Thu Apr 13 20:47:39.839280 2017] [:error] [pid 31204:tid 140522505058048] [client 14.140.161.92:64684]     from email.Utils import parsedate_tz
[Thu Apr 13 20:47:39.839293 2017] [:error] [pid 31204:tid 140522505058048] [client 14.140.161.92:64684]   File "/var/www/api/email/__init__.py", line 1, in <module>
[Thu Apr 13 20:47:39.839321 2017] [:error] [pid 31204:tid 140522505058048] [client 14.140.161.92:64684]     from email_v1 import *
[Thu Apr 13 20:47:39.839329 2017] [:error] [pid 31204:tid 140522505058048] [client 14.140.161.92:64684]   File "/var/www/api/email/email_v1.py", line 2, in <module>
[Thu Apr 13 20:47:39.839400 2017] [:error] [pid 31204:tid 140522505058048] [client 14.140.161.92:64684]     from flask import request
[Thu Apr 13 20:47:39.839427 2017] [:error] [pid 31204:tid 140522505058048] [client 14.140.161.92:64684] ImportError: cannot import name request
[Thu Apr 13 20:49:10.299314 2017] [:error] [pid 31317:tid 139890315261696] [client 14.140.161.92:64689] mod_wsgi (pid=31317): Target WSGI script '/var/www/api/wsgi/flask.wsgi' cannot be loaded as Python module.
[Thu Apr 13 20:49:10.299416 2017] [:error] [pid 31317:tid 139890315261696] [client 14.140.161.92:64689] mod_wsgi (pid=31317): Exception occurred processing WSGI script '/var/www/api/wsgi/flask.wsgi'.
[Thu Apr 13 20:49:10.299438 2017] [:error] [pid 31317:tid 139890315261696] [client 14.140.161.92:64689] Traceback (most recent call last):
[Thu Apr 13 20:49:10.299458 2017] [:error] [pid 31317:tid 139890315261696] [client 14.140.161.92:64689]   File "/var/www/api/wsgi/flask.wsgi", line 7, in <module>
[Thu Apr 13 20:49:10.299516 2017] [:error] [pid 31317:tid 139890315261696] [client 14.140.161.92:64689]     from app import app as application
[Thu Apr 13 20:49:10.299527 2017] [:error] [pid 31317:tid 139890315261696] [client 14.140.161.92:64689]   File "/var/www/api/app.py", line 1, in <module>
[Thu Apr 13 20:49:10.299561 2017] [:error] [pid 31317:tid 139890315261696] [client 14.140.161.92:64689]     from flask import Flask
[Thu Apr 13 20:49:10.299570 2017] [:error] [pid 31317:tid 139890315261696] [client 14.140.161.92:64689]   File "/usr/local/lib/python2.7/dist-packages/flask/__init__.py", line 17, in <module>
[Thu Apr 13 20:49:10.299602 2017] [:error] [pid 31317:tid 139890315261696] [client 14.140.161.92:64689]     from werkzeug.exceptions import abort
[Thu Apr 13 20:49:10.299610 2017] [:error] [pid 31317:tid 139890315261696] [client 14.140.161.92:64689]   File "/usr/local/lib/python2.7/dist-packages/werkzeug/__init__.py", line 152, in <module>
[Thu Apr 13 20:49:10.299664 2017] [:error] [pid 31317:tid 139890315261696] [client 14.140.161.92:64689]     __import__('werkzeug.exceptions')
[Thu Apr 13 20:49:10.299672 2017] [:error] [pid 31317:tid 139890315261696] [client 14.140.161.92:64689]   File "/usr/local/lib/python2.7/dist-packages/werkzeug/exceptions.py", line 71, in <module>
[Thu Apr 13 20:49:10.299805 2017] [:error] [pid 31317:tid 139890315261696] [client 14.140.161.92:64689]     from werkzeug.wrappers import Response
[Thu Apr 13 20:49:10.299814 2017] [:error] [pid 31317:tid 139890315261696] [client 14.140.161.92:64689]   File "/usr/local/lib/python2.7/dist-packages/werkzeug/wrappers.py", line 26, in <module>
[Thu Apr 13 20:49:10.300230 2017] [:error] [pid 31317:tid 139890315261696] [client 14.140.161.92:64689]     from werkzeug.http import HTTP_STATUS_CODES, \\
[Thu Apr 13 20:49:10.300241 2017] [:error] [pid 31317:tid 139890315261696] [client 14.140.161.92:64689]   File "/usr/local/lib/python2.7/dist-packages/werkzeug/http.py", line 24, in <module>
[Thu Apr 13 20:49:10.300446 2017] [:error] [pid 31317:tid 139890315261696] [client 14.140.161.92:64689]     from email.Utils import parsedate_tz
[Thu Apr 13 20:49:10.300455 2017] [:error] [pid 31317:tid 139890315261696] [client 14.140.161.92:64689]   File "/var/www/api/email/__init__.py", line 1, in <module>
[Thu Apr 13 20:49:10.300478 2017] [:error] [pid 31317:tid 139890315261696] [client 14.140.161.92:64689]     from email_v1 import *
[Thu Apr 13 20:49:10.300484 2017] [:error] [pid 31317:tid 139890315261696] [client 14.140.161.92:64689]   File "/var/www/api/email/email_v1.py", line 3, in <module>
[Thu Apr 13 20:49:10.300508 2017] [:error] [pid 31317:tid 139890315261696] [client 14.140.161.92:64689]     from restful import Resource
[Thu Apr 13 20:49:10.300515 2017] [:error] [pid 31317:tid 139890315261696] [client 14.140.161.92:64689]   File "/var/www/api/restful.py", line 1, in <module>
[Thu Apr 13 20:49:10.300537 2017] [:error] [pid 31317:tid 139890315261696] [client 14.140.161.92:64689]     from flask_restful import Resource as BaseResource
[Thu Apr 13 20:49:10.300543 2017] [:error] [pid 31317:tid 139890315261696] [client 14.140.161.92:64689]   File "/usr/local/lib/python2.7/dist-packages/flask_restful/__init__.py", line 5, in <module>
[Thu Apr 13 20:49:10.300706 2017] [:error] [pid 31317:tid 139890315261696] [client 14.140.161.92:64689]     from flask import request, url_for, current_app
[Thu Apr 13 20:49:10.300727 2017] [:error] [pid 31317:tid 139890315261696] [client 14.140.161.92:64689] ImportError: cannot import name request
[Thu Apr 13 20:50:24.899388 2017] [:error] [pid 31432:tid 140053964904192] [client 14.140.161.92:64694] mod_wsgi (pid=31432): Target WSGI script '/var/www/api/wsgi/flask.wsgi' cannot be loaded as Python module.
[Thu Apr 13 20:50:24.899443 2017] [:error] [pid 31432:tid 140053964904192] [client 14.140.161.92:64694] mod_wsgi (pid=31432): Exception occurred processing WSGI script '/var/www/api/wsgi/flask.wsgi'.
[Thu Apr 13 20:50:24.899465 2017] [:error] [pid 31432:tid 140053964904192] [client 14.140.161.92:64694] Traceback (most recent call last):
[Thu Apr 13 20:50:24.899487 2017] [:error] [pid 31432:tid 140053964904192] [client 14.140.161.92:64694]   File "/var/www/api/wsgi/flask.wsgi", line 7, in <module>
[Thu Apr 13 20:50:24.899545 2017] [:error] [pid 31432:tid 140053964904192] [client 14.140.161.92:64694]     from app import app as application
[Thu Apr 13 20:50:24.899555 2017] [:error] [pid 31432:tid 140053964904192] [client 14.140.161.92:64694]   File "/var/www/api/app.py", line 1, in <module>
[Thu Apr 13 20:50:24.899589 2017] [:error] [pid 31432:tid 140053964904192] [client 14.140.161.92:64694]     from flask import Flask
[Thu Apr 13 20:50:24.899597 2017] [:error] [pid 31432:tid 140053964904192] [client 14.140.161.92:64694]   File "/usr/local/lib/python2.7/dist-packages/flask/__init__.py", line 17, in <module>
[Thu Apr 13 20:50:24.899631 2017] [:error] [pid 31432:tid 140053964904192] [client 14.140.161.92:64694]     from werkzeug.exceptions import abort
[Thu Apr 13 20:50:24.899657 2017] [:error] [pid 31432:tid 140053964904192] [client 14.140.161.92:64694]   File "/usr/local/lib/python2.7/dist-packages/werkzeug/__init__.py", line 152, in <module>
[Thu Apr 13 20:50:24.899722 2017] [:error] [pid 31432:tid 140053964904192] [client 14.140.161.92:64694]     __import__('werkzeug.exceptions')
[Thu Apr 13 20:50:24.899731 2017] [:error] [pid 31432:tid 140053964904192] [client 14.140.161.92:64694]   File "/usr/local/lib/python2.7/dist-packages/werkzeug/exceptions.py", line 71, in <module>
[Thu Apr 13 20:50:24.899888 2017] [:error] [pid 31432:tid 140053964904192] [client 14.140.161.92:64694]     from werkzeug.wrappers import Response
[Thu Apr 13 20:50:24.899907 2017] [:error] [pid 31432:tid 140053964904192] [client 14.140.161.92:64694]   File "/usr/local/lib/python2.7/dist-packages/werkzeug/wrappers.py", line 26, in <module>
[Thu Apr 13 20:50:24.900335 2017] [:error] [pid 31432:tid 140053964904192] [client 14.140.161.92:64694]     from werkzeug.http import HTTP_STATUS_CODES, \\
[Thu Apr 13 20:50:24.900346 2017] [:error] [pid 31432:tid 140053964904192] [client 14.140.161.92:64694]   File "/usr/local/lib/python2.7/dist-packages/werkzeug/http.py", line 24, in <module>
[Thu Apr 13 20:50:24.900547 2017] [:error] [pid 31432:tid 140053964904192] [client 14.140.161.92:64694]     from email.Utils import parsedate_tz
[Thu Apr 13 20:50:24.900557 2017] [:error] [pid 31432:tid 140053964904192] [client 14.140.161.92:64694]   File "/var/www/api/email/__init__.py", line 1, in <module>
[Thu Apr 13 20:50:24.900581 2017] [:error] [pid 31432:tid 140053964904192] [client 14.140.161.92:64694]     from email_v1 import *
[Thu Apr 13 20:50:24.900604 2017] [:error] [pid 31432:tid 140053964904192] [client 14.140.161.92:64694]   File "/var/www/api/email/email_v1.py", line 2, in <module>
[Thu Apr 13 20:50:24.900636 2017] [:error] [pid 31432:tid 140053964904192] [client 14.140.161.92:64694]     from flask import request
[Thu Apr 13 20:50:24.900658 2017] [:error] [pid 31432:tid 140053964904192] [client 14.140.161.92:64694] ImportError: cannot import name request
[Thu Apr 13 20:50:51.205217 2017] [:error] [pid 31541:tid 140661839845120] [client 14.140.161.92:64696] mod_wsgi (pid=31541): Target WSGI script '/var/www/api/wsgi/flask.wsgi' cannot be loaded as Python module.
[Thu Apr 13 20:50:51.205278 2017] [:error] [pid 31541:tid 140661839845120] [client 14.140.161.92:64696] mod_wsgi (pid=31541): Exception occurred processing WSGI script '/var/www/api/wsgi/flask.wsgi'.
[Thu Apr 13 20:50:51.205304 2017] [:error] [pid 31541:tid 140661839845120] [client 14.140.161.92:64696] Traceback (most recent call last):
[Thu Apr 13 20:50:51.205333 2017] [:error] [pid 31541:tid 140661839845120] [client 14.140.161.92:64696]   File "/var/www/api/wsgi/flask.wsgi", line 7, in <module>
[Thu Apr 13 20:50:51.205416 2017] [:error] [pid 31541:tid 140661839845120] [client 14.140.161.92:64696]     from app import app as application
[Thu Apr 13 20:50:51.205435 2017] [:error] [pid 31541:tid 140661839845120] [client 14.140.161.92:64696]   File "/var/www/api/app.py", line 1, in <module>
[Thu Apr 13 20:50:51.205483 2017] [:error] [pid 31541:tid 140661839845120] [client 14.140.161.92:64696]     from flask import Flask
[Thu Apr 13 20:50:51.205492 2017] [:error] [pid 31541:tid 140661839845120] [client 14.140.161.92:64696]   File "/usr/local/lib/python2.7/dist-packages/flask/__init__.py", line 17, in <module>
[Thu Apr 13 20:50:51.205527 2017] [:error] [pid 31541:tid 140661839845120] [client 14.140.161.92:64696]     from werkzeug.exceptions import abort
[Thu Apr 13 20:50:51.205535 2017] [:error] [pid 31541:tid 140661839845120] [client 14.140.161.92:64696]   File "/usr/local/lib/python2.7/dist-packages/werkzeug/__init__.py", line 152, in <module>
[Thu Apr 13 20:50:51.205593 2017] [:error] [pid 31541:tid 140661839845120] [client 14.140.161.92:64696]     __import__('werkzeug.exceptions')
[Thu Apr 13 20:50:51.205601 2017] [:error] [pid 31541:tid 140661839845120] [client 14.140.161.92:64696]   File "/usr/local/lib/python2.7/dist-packages/werkzeug/exceptions.py", line 71, in <module>
[Thu Apr 13 20:50:51.205800 2017] [:error] [pid 31541:tid 140661839845120] [client 14.140.161.92:64696]     from werkzeug.wrappers import Response
[Thu Apr 13 20:50:51.205813 2017] [:error] [pid 31541:tid 140661839845120] [client 14.140.161.92:64696]   File "/usr/local/lib/python2.7/dist-packages/werkzeug/wrappers.py", line 26, in <module>
[Thu Apr 13 20:50:51.206322 2017] [:error] [pid 31541:tid 140661839845120] [client 14.140.161.92:64696]     from werkzeug.http import HTTP_STATUS_CODES, \\
[Thu Apr 13 20:50:51.206337 2017] [:error] [pid 31541:tid 140661839845120] [client 14.140.161.92:64696]   File "/usr/local/lib/python2.7/dist-packages/werkzeug/http.py", line 24, in <module>
[Thu Apr 13 20:50:51.206560 2017] [:error] [pid 31541:tid 140661839845120] [client 14.140.161.92:64696]     from email.Utils import parsedate_tz
[Thu Apr 13 20:50:51.206571 2017] [:error] [pid 31541:tid 140661839845120] [client 14.140.161.92:64696]   File "/var/www/api/email/__init__.py", line 1, in <module>
[Thu Apr 13 20:50:51.206597 2017] [:error] [pid 31541:tid 140661839845120] [client 14.140.161.92:64696]     from email_v1 import *
[Thu Apr 13 20:50:51.206604 2017] [:error] [pid 31541:tid 140661839845120] [client 14.140.161.92:64696]   File "/var/www/api/email/email_v1.py", line 2, in <module>
[Thu Apr 13 20:50:51.206634 2017] [:error] [pid 31541:tid 140661839845120] [client 14.140.161.92:64696]     from flask import request
[Thu Apr 13 20:50:51.206657 2017] [:error] [pid 31541:tid 140661839845120] [client 14.140.161.92:64696] ImportError: cannot import name request
[Thu Apr 13 20:51:58.655779 2017] [:error] [pid 31660:tid 139872094340864] [client 14.140.161.92:64699] mod_wsgi (pid=31660): Target WSGI script '/var/www/api/wsgi/flask.wsgi' cannot be loaded as Python module.
[Thu Apr 13 20:51:58.655852 2017] [:error] [pid 31660:tid 139872094340864] [client 14.140.161.92:64699] mod_wsgi (pid=31660): Exception occurred processing WSGI script '/var/www/api/wsgi/flask.wsgi'.
[Thu Apr 13 20:51:58.655885 2017] [:error] [pid 31660:tid 139872094340864] [client 14.140.161.92:64699] Traceback (most recent call last):
[Thu Apr 13 20:51:58.655917 2017] [:error] [pid 31660:tid 139872094340864] [client 14.140.161.92:64699]   File "/var/www/api/wsgi/flask.wsgi", line 7, in <module>
[Thu Apr 13 20:51:58.656061 2017] [:error] [pid 31660:tid 139872094340864] [client 14.140.161.92:64699]     from app import app as application
[Thu Apr 13 20:51:58.656079 2017] [:error] [pid 31660:tid 139872094340864] [client 14.140.161.92:64699]   File "/var/www/api/app.py", line 1, in <module>
[Thu Apr 13 20:51:58.656135 2017] [:error] [pid 31660:tid 139872094340864] [client 14.140.161.92:64699]     from flask import Flask
[Thu Apr 13 20:51:58.656148 2017] [:error] [pid 31660:tid 139872094340864] [client 14.140.161.92:64699]   File "/usr/local/lib/python2.7/dist-packages/flask/__init__.py", line 17, in <module>
[Thu Apr 13 20:51:58.656206 2017] [:error] [pid 31660:tid 139872094340864] [client 14.140.161.92:64699]     from werkzeug.exceptions import abort
[Thu Apr 13 20:51:58.656220 2017] [:error] [pid 31660:tid 139872094340864] [client 14.140.161.92:64699]   File "/usr/local/lib/python2.7/dist-packages/werkzeug/__init__.py", line 152, in <module>
[Thu Apr 13 20:51:58.656310 2017] [:error] [pid 31660:tid 139872094340864] [client 14.140.161.92:64699]     __import__('werkzeug.exceptions')
[Thu Apr 13 20:51:58.656323 2017] [:error] [pid 31660:tid 139872094340864] [client 14.140.161.92:64699]   File "/usr/local/lib/python2.7/dist-packages/werkzeug/exceptions.py", line 71, in <module>
[Thu Apr 13 20:51:58.656540 2017] [:error] [pid 31660:tid 139872094340864] [client 14.140.161.92:64699]     from werkzeug.wrappers import Response
[Thu Apr 13 20:51:58.656555 2017] [:error] [pid 31660:tid 139872094340864] [client 14.140.161.92:64699]   File "/usr/local/lib/python2.7/dist-packages/werkzeug/wrappers.py", line 26, in <module>
[Thu Apr 13 20:51:58.657214 2017] [:error] [pid 31660:tid 139872094340864] [client 14.140.161.92:64699]     from werkzeug.http import HTTP_STATUS_CODES, \\
[Thu Apr 13 20:51:58.657232 2017] [:error] [pid 31660:tid 139872094340864] [client 14.140.161.92:64699]   File "/usr/local/lib/python2.7/dist-packages/werkzeug/http.py", line 24, in <module>
[Thu Apr 13 20:51:58.657561 2017] [:error] [pid 31660:tid 139872094340864] [client 14.140.161.92:64699]     from email.Utils import parsedate_tz
[Thu Apr 13 20:51:58.657576 2017] [:error] [pid 31660:tid 139872094340864] [client 14.140.161.92:64699]   File "/var/www/api/email/__init__.py", line 1, in <module>
[Thu Apr 13 20:51:58.657614 2017] [:error] [pid 31660:tid 139872094340864] [client 14.140.161.92:64699]     from email_v1 import *
[Thu Apr 13 20:51:58.657641 2017] [:error] [pid 31660:tid 139872094340864] [client 14.140.161.92:64699]   File "/var/www/api/email/email_v1.py", line 2, in <module>
[Thu Apr 13 20:51:58.657689 2017] [:error] [pid 31660:tid 139872094340864] [client 14.140.161.92:64699]     from flask import request
[Thu Apr 13 20:51:58.657722 2017] [:error] [pid 31660:tid 139872094340864] [client 14.140.161.92:64699] ImportError: cannot import name request
[Thu Apr 13 20:53:06.438127 2017] [:error] [pid 31769:tid 140195810748160] [client 14.140.161.92:64702] mod_wsgi (pid=31769): Target WSGI script '/var/www/api/wsgi/flask.wsgi' cannot be loaded as Python module.
[Thu Apr 13 20:53:06.438192 2017] [:error] [pid 31769:tid 140195810748160] [client 14.140.161.92:64702] mod_wsgi (pid=31769): Exception occurred processing WSGI script '/var/www/api/wsgi/flask.wsgi'.
[Thu Apr 13 20:53:06.438217 2017] [:error] [pid 31769:tid 140195810748160] [client 14.140.161.92:64702] Traceback (most recent call last):
[Thu Apr 13 20:53:06.438239 2017] [:error] [pid 31769:tid 140195810748160] [client 14.140.161.92:64702]   File "/var/www/api/wsgi/flask.wsgi", line 7, in <module>
[Thu Apr 13 20:53:06.438300 2017] [:error] [pid 31769:tid 140195810748160] [client 14.140.161.92:64702]     from app import app as application
[Thu Apr 13 20:53:06.438311 2017] [:error] [pid 31769:tid 140195810748160] [client 14.140.161.92:64702]   File "/var/www/api/app.py", line 1, in <module>
[Thu Apr 13 20:53:06.438363 2017] [:error] [pid 31769:tid 140195810748160] [client 14.140.161.92:64702]     from flask import Flask
[Thu Apr 13 20:53:06.438376 2017] [:error] [pid 31769:tid 140195810748160] [client 14.140.161.92:64702]   File "/usr/local/lib/python2.7/dist-packages/flask/__init__.py", line 17, in <module>
[Thu Apr 13 20:53:06.438421 2017] [:error] [pid 31769:tid 140195810748160] [client 14.140.161.92:64702]     from werkzeug.exceptions import abort
[Thu Apr 13 20:53:06.438430 2017] [:error] [pid 31769:tid 140195810748160] [client 14.140.161.92:64702]   File "/usr/local/lib/python2.7/dist-packages/werkzeug/__init__.py", line 152, in <module>
[Thu Apr 13 20:53:06.438488 2017] [:error] [pid 31769:tid 140195810748160] [client 14.140.161.92:64702]     __import__('werkzeug.exceptions')
[Thu Apr 13 20:53:06.438497 2017] [:error] [pid 31769:tid 140195810748160] [client 14.140.161.92:64702]   File "/usr/local/lib/python2.7/dist-packages/werkzeug/exceptions.py", line 71, in <module>
[Thu Apr 13 20:53:06.438637 2017] [:error] [pid 31769:tid 140195810748160] [client 14.140.161.92:64702]     from werkzeug.wrappers import Response
[Thu Apr 13 20:53:06.438646 2017] [:error] [pid 31769:tid 140195810748160] [client 14.140.161.92:64702]   File "/usr/local/lib/python2.7/dist-packages/werkzeug/wrappers.py", line 26, in <module>
[Thu Apr 13 20:53:06.439076 2017] [:error] [pid 31769:tid 140195810748160] [client 14.140.161.92:64702]     from werkzeug.http import HTTP_STATUS_CODES, \\
[Thu Apr 13 20:53:06.439089 2017] [:error] [pid 31769:tid 140195810748160] [client 14.140.161.92:64702]   File "/usr/local/lib/python2.7/dist-packages/werkzeug/http.py", line 24, in <module>
[Thu Apr 13 20:53:06.439367 2017] [:error] [pid 31769:tid 140195810748160] [client 14.140.161.92:64702]     from email.Utils import parsedate_tz
[Thu Apr 13 20:53:06.439382 2017] [:error] [pid 31769:tid 140195810748160] [client 14.140.161.92:64702]   File "/var/www/api/email/__init__.py", line 1, in <module>
[Thu Apr 13 20:53:06.439412 2017] [:error] [pid 31769:tid 140195810748160] [client 14.140.161.92:64702]     from email_v1 import *
[Thu Apr 13 20:53:06.439420 2017] [:error] [pid 31769:tid 140195810748160] [client 14.140.161.92:64702]   File "/var/www/api/email/email_v1.py", line 2, in <module>
[Thu Apr 13 20:53:06.439445 2017] [:error] [pid 31769:tid 140195810748160] [client 14.140.161.92:64702]     from flask import request
[Thu Apr 13 20:53:06.439468 2017] [:error] [pid 31769:tid 140195810748160] [client 14.140.161.92:64702] ImportError: cannot import name request
[Thu Apr 13 20:53:52.258671 2017] [:error] [pid 31769:tid 140195802355456] [client 14.140.161.92:64706] mod_wsgi (pid=31769): Target WSGI script '/var/www/api/wsgi/flask.wsgi' cannot be loaded as Python module.
[Thu Apr 13 20:53:52.258734 2017] [:error] [pid 31769:tid 140195802355456] [client 14.140.161.92:64706] mod_wsgi (pid=31769): Exception occurred processing WSGI script '/var/www/api/wsgi/flask.wsgi'.
[Thu Apr 13 20:53:52.258757 2017] [:error] [pid 31769:tid 140195802355456] [client 14.140.161.92:64706] Traceback (most recent call last):
[Thu Apr 13 20:53:52.258779 2017] [:error] [pid 31769:tid 140195802355456] [client 14.140.161.92:64706]   File "/var/www/api/wsgi/flask.wsgi", line 7, in <module>
[Thu Apr 13 20:53:52.258813 2017] [:error] [pid 31769:tid 140195802355456] [client 14.140.161.92:64706]     from app import app as application
[Thu Apr 13 20:53:52.258821 2017] [:error] [pid 31769:tid 140195802355456] [client 14.140.161.92:64706]   File "/var/www/api/app.py", line 1, in <module>
[Thu Apr 13 20:53:52.258831 2017] [:error] [pid 31769:tid 140195802355456] [client 14.140.161.92:64706]     from flask import Flask
[Thu Apr 13 20:53:52.258837 2017] [:error] [pid 31769:tid 140195802355456] [client 14.140.161.92:64706]   File "/usr/local/lib/python2.7/dist-packages/flask/__init__.py", line 17, in <module>
[Thu Apr 13 20:53:52.258847 2017] [:error] [pid 31769:tid 140195802355456] [client 14.140.161.92:64706]     from werkzeug.exceptions import abort
[Thu Apr 13 20:53:52.258852 2017] [:error] [pid 31769:tid 140195802355456] [client 14.140.161.92:64706]   File "/usr/local/lib/python2.7/dist-packages/werkzeug/__init__.py", line 152, in <module>
[Thu Apr 13 20:53:52.258861 2017] [:error] [pid 31769:tid 140195802355456] [client 14.140.161.92:64706]     __import__('werkzeug.exceptions')
[Thu Apr 13 20:53:52.258866 2017] [:error] [pid 31769:tid 140195802355456] [client 14.140.161.92:64706]   File "/usr/local/lib/python2.7/dist-packages/werkzeug/exceptions.py", line 71, in <module>
[Thu Apr 13 20:53:52.258874 2017] [:error] [pid 31769:tid 140195802355456] [client 14.140.161.92:64706]     from werkzeug.wrappers import Response
[Thu Apr 13 20:53:52.258879 2017] [:error] [pid 31769:tid 140195802355456] [client 14.140.161.92:64706]   File "/usr/local/lib/python2.7/dist-packages/werkzeug/wrappers.py", line 26, in <module>
[Thu Apr 13 20:53:52.258887 2017] [:error] [pid 31769:tid 140195802355456] [client 14.140.161.92:64706]     from werkzeug.http import HTTP_STATUS_CODES, \\
[Thu Apr 13 20:53:52.258891 2017] [:error] [pid 31769:tid 140195802355456] [client 14.140.161.92:64706]   File "/usr/local/lib/python2.7/dist-packages/werkzeug/http.py", line 24, in <module>
[Thu Apr 13 20:53:52.258900 2017] [:error] [pid 31769:tid 140195802355456] [client 14.140.161.92:64706]     from email.Utils import parsedate_tz
[Thu Apr 13 20:53:52.258904 2017] [:error] [pid 31769:tid 140195802355456] [client 14.140.161.92:64706]   File "/var/www/api/email/__init__.py", line 1, in <module>
[Thu Apr 13 20:53:52.258913 2017] [:error] [pid 31769:tid 140195802355456] [client 14.140.161.92:64706]     from email_v1 import *
[Thu Apr 13 20:53:52.258917 2017] [:error] [pid 31769:tid 140195802355456] [client 14.140.161.92:64706]   File "/var/www/api/email/email_v1.py", line 2, in <module>
[Thu Apr 13 20:53:52.258925 2017] [:error] [pid 31769:tid 140195802355456] [client 14.140.161.92:64706]     from flask import request
[Thu Apr 13 20:53:52.258952 2017] [:error] [pid 31769:tid 140195802355456] [client 14.140.161.92:64706] ImportError: cannot import name request
[Thu Apr 13 20:57:56.564233 2017] [:error] [pid 31919:tid 140042441815808] [client 14.140.161.92:64777] mod_wsgi (pid=31919): Target WSGI script '/var/www/api/wsgi/flask.wsgi' cannot be loaded as Python module.
[Thu Apr 13 20:57:56.564307 2017] [:error] [pid 31919:tid 140042441815808] [client 14.140.161.92:64777] mod_wsgi (pid=31919): Exception occurred processing WSGI script '/var/www/api/wsgi/flask.wsgi'.
[Thu Apr 13 20:57:56.564343 2017] [:error] [pid 31919:tid 140042441815808] [client 14.140.161.92:64777] Traceback (most recent call last):
[Thu Apr 13 20:57:56.564392 2017] [:error] [pid 31919:tid 140042441815808] [client 14.140.161.92:64777]   File "/var/www/api/wsgi/flask.wsgi", line 7, in <module>
[Thu Apr 13 20:57:56.564482 2017] [:error] [pid 31919:tid 140042441815808] [client 14.140.161.92:64777]     from app import app as application
[Thu Apr 13 20:57:56.564499 2017] [:error] [pid 31919:tid 140042441815808] [client 14.140.161.92:64777]   File "/var/www/api/app.py", line 1, in <module>
[Thu Apr 13 20:57:56.564560 2017] [:error] [pid 31919:tid 140042441815808] [client 14.140.161.92:64777]     from flask import Flask
[Thu Apr 13 20:57:56.564575 2017] [:error] [pid 31919:tid 140042441815808] [client 14.140.161.92:64777]   File "/usr/local/lib/python2.7/dist-packages/flask/__init__.py", line 17, in <module>
[Thu Apr 13 20:57:56.564640 2017] [:error] [pid 31919:tid 140042441815808] [client 14.140.161.92:64777]     from werkzeug.exceptions import abort
[Thu Apr 13 20:57:56.564657 2017] [:error] [pid 31919:tid 140042441815808] [client 14.140.161.92:64777]   File "/usr/local/lib/python2.7/dist-packages/werkzeug/__init__.py", line 152, in <module>
[Thu Apr 13 20:57:56.564755 2017] [:error] [pid 31919:tid 140042441815808] [client 14.140.161.92:64777]     __import__('werkzeug.exceptions')
[Thu Apr 13 20:57:56.564772 2017] [:error] [pid 31919:tid 140042441815808] [client 14.140.161.92:64777]   File "/usr/local/lib/python2.7/dist-packages/werkzeug/exceptions.py", line 71, in <module>
[Thu Apr 13 20:57:56.565008 2017] [:error] [pid 31919:tid 140042441815808] [client 14.140.161.92:64777]     from werkzeug.wrappers import Response
[Thu Apr 13 20:57:56.565028 2017] [:error] [pid 31919:tid 140042441815808] [client 14.140.161.92:64777]   File "/usr/local/lib/python2.7/dist-packages/werkzeug/wrappers.py", line 26, in <module>
[Thu Apr 13 20:57:56.565620 2017] [:error] [pid 31919:tid 140042441815808] [client 14.140.161.92:64777]     from werkzeug.http import HTTP_STATUS_CODES, \\
[Thu Apr 13 20:57:56.565644 2017] [:error] [pid 31919:tid 140042441815808] [client 14.140.161.92:64777]   File "/usr/local/lib/python2.7/dist-packages/werkzeug/http.py", line 24, in <module>
[Thu Apr 13 20:57:56.566033 2017] [:error] [pid 31919:tid 140042441815808] [client 14.140.161.92:64777]     from email.Utils import parsedate_tz
[Thu Apr 13 20:57:56.566056 2017] [:error] [pid 31919:tid 140042441815808] [client 14.140.161.92:64777]   File "/var/www/api/email/__init__.py", line 1, in <module>
[Thu Apr 13 20:57:56.566110 2017] [:error] [pid 31919:tid 140042441815808] [client 14.140.161.92:64777]     from email_v1 import *
[Thu Apr 13 20:57:56.566124 2017] [:error] [pid 31919:tid 140042441815808] [client 14.140.161.92:64777]   File "/var/www/api/email/email_v1.py", line 2, in <module>
[Thu Apr 13 20:57:56.566202 2017] [:error] [pid 31919:tid 140042441815808] [client 14.140.161.92:64777]     from flask import request
[Thu Apr 13 20:57:56.566238 2017] [:error] [pid 31919:tid 140042441815808] [client 14.140.161.92:64777] ImportError: cannot import name request
[Thu Apr 13 20:58:03.606114 2017] [:error] [pid 31919:tid 140042433423104] [client 14.140.161.92:64778] mod_wsgi (pid=31919): Target WSGI script '/var/www/api/wsgi/flask.wsgi' cannot be loaded as Python module.
[Thu Apr 13 20:58:03.606161 2017] [:error] [pid 31919:tid 140042433423104] [client 14.140.161.92:64778] mod_wsgi (pid=31919): Exception occurred processing WSGI script '/var/www/api/wsgi/flask.wsgi'.
[Thu Apr 13 20:58:03.606183 2017] [:error] [pid 31919:tid 140042433423104] [client 14.140.161.92:64778] Traceback (most recent call last):
[Thu Apr 13 20:58:03.606203 2017] [:error] [pid 31919:tid 140042433423104] [client 14.140.161.92:64778]   File "/var/www/api/wsgi/flask.wsgi", line 7, in <module>
[Thu Apr 13 20:58:03.606239 2017] [:error] [pid 31919:tid 140042433423104] [client 14.140.161.92:64778]     from app import app as application
[Thu Apr 13 20:58:03.606252 2017] [:error] [pid 31919:tid 140042433423104] [client 14.140.161.92:64778]   File "/var/www/api/app.py", line 1, in <module>
[Thu Apr 13 20:58:03.606272 2017] [:error] [pid 31919:tid 140042433423104] [client 14.140.161.92:64778]     from flask import Flask
[Thu Apr 13 20:58:03.606302 2017] [:error] [pid 31919:tid 140042433423104] [client 14.140.161.92:64778]   File "/usr/local/lib/python2.7/dist-packages/flask/__init__.py", line 17, in <module>
[Thu Apr 13 20:58:03.606318 2017] [:error] [pid 31919:tid 140042433423104] [client 14.140.161.92:64778]     from werkzeug.exceptions import abort
[Thu Apr 13 20:58:03.606324 2017] [:error] [pid 31919:tid 140042433423104] [client 14.140.161.92:64778]   File "/usr/local/lib/python2.7/dist-packages/werkzeug/__init__.py", line 152, in <module>
[Thu Apr 13 20:58:03.606334 2017] [:error] [pid 31919:tid 140042433423104] [client 14.140.161.92:64778]     __import__('werkzeug.exceptions')
[Thu Apr 13 20:58:03.606339 2017] [:error] [pid 31919:tid 140042433423104] [client 14.140.161.92:64778]   File "/usr/local/lib/python2.7/dist-packages/werkzeug/exceptions.py", line 71, in <module>
[Thu Apr 13 20:58:03.606348 2017] [:error] [pid 31919:tid 140042433423104] [client 14.140.161.92:64778]     from werkzeug.wrappers import Response
[Thu Apr 13 20:58:03.606353 2017] [:error] [pid 31919:tid 140042433423104] [client 14.140.161.92:64778]   File "/usr/local/lib/python2.7/dist-packages/werkzeug/wrappers.py", line 26, in <module>
[Thu Apr 13 20:58:03.606362 2017] [:error] [pid 31919:tid 140042433423104] [client 14.140.161.92:64778]     from werkzeug.http import HTTP_STATUS_CODES, \\
[Thu Apr 13 20:58:03.606367 2017] [:error] [pid 31919:tid 140042433423104] [client 14.140.161.92:64778]   File "/usr/local/lib/python2.7/dist-packages/werkzeug/http.py", line 24, in <module>
[Thu Apr 13 20:58:03.606375 2017] [:error] [pid 31919:tid 140042433423104] [client 14.140.161.92:64778]     from email.Utils import parsedate_tz
[Thu Apr 13 20:58:03.606381 2017] [:error] [pid 31919:tid 140042433423104] [client 14.140.161.92:64778]   File "/var/www/api/email/__init__.py", line 1, in <module>
[Thu Apr 13 20:58:03.606389 2017] [:error] [pid 31919:tid 140042433423104] [client 14.140.161.92:64778]     from email_v1 import *
[Thu Apr 13 20:58:03.606394 2017] [:error] [pid 31919:tid 140042433423104] [client 14.140.161.92:64778]   File "/var/www/api/email/email_v1.py", line 2, in <module>
[Thu Apr 13 20:58:03.606403 2017] [:error] [pid 31919:tid 140042433423104] [client 14.140.161.92:64778]     from flask import request
[Thu Apr 13 20:58:03.606423 2017] [:error] [pid 31919:tid 140042433423104] [client 14.140.161.92:64778] ImportError: cannot import name request
